time: 2014-01-01 21:30:30.379762Z
tags: worker-0
test: tempest.scenario.test_large_ops.TestLargeOpsScenario.test_large_ops_scenario[compute,image]
time: 2014-01-01 21:31:25.334330Z
failure: tempest.scenario.test_large_ops.TestLargeOpsScenario.test_large_ops_scenario[compute,image] [ multipart
Content-Type: text/plain;charset="utf8"
pythonlogging:''
0
Content-Type: text/plain;charset="utf8"
stderr
0
Content-Type: text/plain;charset="utf8"
stdout
0
Content-Type: text/x-traceback;charset="utf8",language="python"
traceback
485
Traceback (most recent call last):
  File "/home/os1/tempest/tempest/scenario/test_large_ops.py", line 99, in test_large_ops_scenario
    self.nova_boot()
  File "/home/os1/tempest/tempest/scenario/test_large_ops.py", line 92, in nova_boot
    self._wait_for_server_status('ACTIVE')
  File "/home/os1/tempest/tempest/scenario/test_large_ops.py", line 43, in _wait_for_server_status
    self.compute_client.servers, server.id, status)
  File "/home/os1/tempest/tempest/scenario/manager.py", line 304, in status_timeout
    not_found_exception=not_found_exception)
  File "/home/os1/tempest/tempest/scenario/manager.py", line 358, in _status_timeout
    self.config.compute.build_interval):
  File "/home/os1/tempest/tempest/test.py", line 290, in call_until_true
    if func():
  File "/home/os1/tempest/tempest/scenario/manager.py", line 349, in check_status
    raise exceptions.BuildErrorException(message)
BuildErrorException: Server %(server_id)s failed to build and is in ERROR status
Details: <Server: scenario-server--tempest-408987064-afd136a5-786f-445a-bf5c-2a45d0113fb1> failed to get to expected status.                           In ERROR state.
0
]
tags: -worker-0
time: 2014-01-01 21:31:47.695721Z
tags: worker-0
test: process-returncode
time: 2014-01-01 21:31:47.695721Z
failure: process-returncode [ multipart
Content-Type: test/plain;charset=utf8
traceback
C
returncode 10
]
tags: -worker-0
