time: 2014-01-09 10:02:00.609312Z
tags: worker-0
test: setUpClass (tempest.scenario.test_volume_boot_pattern.TestVolumeBootPattern)
time: 2014-01-09 10:02:00.609312Z
failure: setUpClass (tempest.scenario.test_volume_boot_pattern.TestVolumeBootPattern) [ multipart
Content-Type: text/x-traceback;charset="utf8",language="python"
traceback
807
Traceback (most recent call last):
  File "/home/os1/tempest/tempest/scenario/test_volume_boot_pattern.py", line 49, in setUpClass
    super(TestVolumeBootPattern, cls).setUpClass()
  File "/home/os1/tempest/tempest/scenario/manager.py", line 500, in setUpClass
    super(NetworkScenarioTest, cls).setUpClass()
  File "/home/os1/tempest/tempest/scenario/manager.py", line 211, in setUpClass
    username, tenant_name, password = cls.credentials()
  File "/home/os1/tempest/tempest/scenario/manager.py", line 226, in credentials
    return cls.isolated_creds.get_primary_creds()
  File "/home/os1/tempest/tempest/common/isolated_creds.py", line 333, in get_primary_creds
    self._get_tenant_id(tenant))
  File "/home/os1/tempest/tempest/common/isolated_creds.py", line 202, in _create_network_resources
    network = self._create_network(network_name, tenant_id)
  File "/home/os1/tempest/tempest/common/isolated_creds.py", line 225, in _create_network
    resp_body = self.network_admin_client.create_network(body)
  File "/usr/local/lib/python2.7/dist-packages/neutronclient/v2_0/client.py", line 108, in with_params
    ret = self.function(instance, *args, **kwargs)
  File "/usr/local/lib/python2.7/dist-packages/neutronclient/v2_0/client.py", line 335, in create_network
    return self.post(self.networks_path, body=body)
  File "/usr/local/lib/python2.7/dist-packages/neutronclient/v2_0/client.py", line 1188, in post
    headers=headers, params=params)
  File "/usr/local/lib/python2.7/dist-packages/neutronclient/v2_0/client.py", line 1111, in do_request
    self._handle_fault_response(status_code, replybody)
  File "/usr/local/lib/python2.7/dist-packages/neutronclient/v2_0/client.py", line 1081, in _handle_fault_response
    exception_handler_v20(status_code, des_error_body)
  File "/usr/local/lib/python2.7/dist-packages/neutronclient/v2_0/client.py", line 88, in exception_handler_v20
    message=message)
NeutronClientException: <html><body><h1>503 Service Unavailable</h1>
No server is available to handle this request.
</body></html>

0
]
tags: -worker-0
time: 2014-01-09 10:02:00.874558Z
tags: worker-0
test: process-returncode
time: 2014-01-09 10:02:00.874558Z
failure: process-returncode [ multipart
Content-Type: test/plain;charset=utf8
traceback
C
returncode 10
]
tags: -worker-0
