time: 2014-01-09 12:02:42.478899Z
tags: worker-0
test: tempest.scenario.test_volume_boot_pattern.TestVolumeBootPattern.test_volume_boot_pattern[compute,image,volume]
time: 2014-01-09 12:02:57.643273Z
failure: tempest.scenario.test_volume_boot_pattern.TestVolumeBootPattern.test_volume_boot_pattern[compute,image,volume] [ multipart
Content-Type: text/plain;charset="utf8"
pythonlogging:''
0
Content-Type: text/plain;charset="utf8"
stderr
0
Content-Type: text/plain;charset="utf8"
stdout
0
Content-Type: text/x-traceback;charset="utf8",language="python"
traceback
50E
Traceback (most recent call last):
  File "/home/os1/tempest/tempest/scenario/test_volume_boot_pattern.py", line 185, in test_volume_boot_pattern
    self.create_loginable_secgroup_rule()
  File "/home/os1/tempest/tempest/scenario/manager.py", line 367, in create_loginable_secgroup_rule
    sgs = client.security_groups.list()
  File "/usr/local/lib/python2.7/dist-packages/novaclient/v1_1/security_groups.py", line 96, in list
    'security_groups')
  File "/usr/local/lib/python2.7/dist-packages/novaclient/base.py", line 61, in _list
    _resp, body = self.api.client.get(url)
  File "/usr/local/lib/python2.7/dist-packages/novaclient/client.py", line 229, in get
    return self._cs_request(url, 'GET', **kwargs)
  File "/usr/local/lib/python2.7/dist-packages/novaclient/client.py", line 213, in _cs_request
    **kwargs)
  File "/usr/local/lib/python2.7/dist-packages/novaclient/client.py", line 195, in _time_request
    resp, body = self.request(url, method, **kwargs)
  File "/usr/local/lib/python2.7/dist-packages/novaclient/client.py", line 189, in request
    raise exceptions.from_response(resp, body, url, method)
ClientException: The server has either erred or is incapable of performing the requested operation. (HTTP 500) (Request-ID: req-419f9d05-f2ca-41e0-9007-004abfc79258)
0
]
tags: -worker-0
time: 2014-01-09 12:02:58.856592Z
tags: worker-0
test: tearDownClass (tempest.scenario.test_volume_boot_pattern.TestVolumeBootPattern)
time: 2014-01-09 12:02:58.856592Z
failure: tearDownClass (tempest.scenario.test_volume_boot_pattern.TestVolumeBootPattern) [ multipart
Content-Type: text/x-traceback;charset="utf8",language="python"
traceback
516
Traceback (most recent call last):
  File "/home/os1/tempest/tempest/scenario/manager.py", line 272, in tearDownClass
    cls.isolated_creds.clear_isolated_creds()
  File "/home/os1/tempest/tempest/common/isolated_creds.py", line 464, in clear_isolated_creds
    self._delete_user(user.id)
  File "/home/os1/tempest/tempest/common/isolated_creds.py", line 141, in _delete_user
    self.identity_admin_client.users.delete(user)
  File "/usr/local/lib/python2.7/dist-packages/keystoneclient/v2_0/users.py", line 101, in delete
    return self._delete("/users/%s" % base.getid(user))
  File "/usr/local/lib/python2.7/dist-packages/keystoneclient/base.py", line 201, in _delete
    return self.client.delete(url)
  File "/usr/local/lib/python2.7/dist-packages/keystoneclient/httpclient.py", line 670, in delete
    return self._cs_request(url, 'DELETE', **kwargs)
  File "/usr/local/lib/python2.7/dist-packages/keystoneclient/httpclient.py", line 651, in _cs_request
    **kwargs)
  File "/usr/local/lib/python2.7/dist-packages/keystoneclient/httpclient.py", line 610, in request
    **request_kwargs)
  File "/usr/local/lib/python2.7/dist-packages/keystoneclient/httpclient.py", line 124, in request
    raise exceptions.from_response(resp, method, url)
ServiceUnavailable: Service Unavailable (HTTP 503)
0
]
tags: -worker-0
time: 2014-01-09 12:02:59.586061Z
tags: worker-0
test: process-returncode
time: 2014-01-09 12:02:59.586061Z
failure: process-returncode [ multipart
Content-Type: test/plain;charset=utf8
traceback
C
returncode 10
]
tags: -worker-0
