time: 2014-01-16 10:53:47.741784Z
tags: worker-0
test: tempest.scenario.test_volume_boot_pattern.TestVolumeBootPattern.test_volume_boot_pattern[compute,image,volume]
time: 2014-01-16 10:57:16.792453Z
failure: tempest.scenario.test_volume_boot_pattern.TestVolumeBootPattern.test_volume_boot_pattern[compute,image,volume] [ multipart
Content-Type: text/plain;charset="utf8"
pythonlogging:''
0
Content-Type: text/plain;charset="utf8"
stderr
0
Content-Type: text/plain;charset="utf8"
stdout
0
Content-Type: text/x-traceback;charset="utf8",language="python"
traceback
6E7
Traceback (most recent call last):
  File "/home/os1/tempest/tempest/scenario/test_volume_boot_pattern.py", line 189, in test_volume_boot_pattern
    volume_origin = self._create_volume_from_image(image_id)
  File "/home/os1/tempest/tempest/scenario/test_volume_boot_pattern.py", line 90, in _create_volume_from_image
    return self.create_volume(name=vol_name, imageRef=img_uuid)
  File "/home/os1/tempest/tempest/scenario/manager.py", line 433, in create_volume
    self.status_timeout(client.volumes, volume.id, 'available')
  File "/home/os1/tempest/tempest/scenario/manager.py", line 304, in status_timeout
    not_found_exception=not_found_exception)
  File "/home/os1/tempest/tempest/scenario/manager.py", line 358, in _status_timeout
    self.config.compute.build_interval):
  File "/home/os1/tempest/tempest/test.py", line 290, in call_until_true
    if func():
  File "/home/os1/tempest/tempest/scenario/manager.py", line 338, in check_status
    thing = things.get(thing_id)
  File "/usr/local/lib/python2.7/dist-packages/cinderclient/v1/volumes.py", line 196, in get
    return self._get("/volumes/%s" % volume_id, "volume")
  File "/usr/local/lib/python2.7/dist-packages/cinderclient/base.py", line 145, in _get
    resp, body = self.api.client.get(url)
  File "/usr/local/lib/python2.7/dist-packages/cinderclient/client.py", line 207, in get
    return self._cs_request(url, 'GET', **kwargs)
  File "/usr/local/lib/python2.7/dist-packages/cinderclient/client.py", line 174, in _cs_request
    **kwargs)
  File "/usr/local/lib/python2.7/dist-packages/cinderclient/client.py", line 157, in request
    raise exceptions.from_response(resp, body)
NotFound: The resource could not be found. (HTTP 404) (Request-ID: req-6aa76d0b-8c58-41cd-ae90-67daba365f73)
0
]
tags: -worker-0
time: 2014-01-16 10:57:39.192939Z
tags: worker-0
test: process-returncode
time: 2014-01-16 10:57:39.192939Z
failure: process-returncode [ multipart
Content-Type: test/plain;charset=utf8
traceback
C
returncode 10
]
tags: -worker-0
