time: 2014-01-17 14:31:21.484600Z
tags: worker-0
test: setUpClass (tempest.scenario.test_minimum_basic.TestMinimumBasicScenario)
time: 2014-01-17 14:31:21.484600Z
failure: setUpClass (tempest.scenario.test_minimum_basic.TestMinimumBasicScenario) [ multipart
Content-Type: text/x-traceback;charset="utf8",language="python"
traceback
7DD
Traceback (most recent call last):
  File "/home/os1/tempest/tempest/scenario/test_minimum_basic.py", line 52, in setUpClass
    super(TestMinimumBasicScenario, cls).setUpClass()
  File "/home/os1/tempest/tempest/scenario/manager.py", line 500, in setUpClass
    super(NetworkScenarioTest, cls).setUpClass()
  File "/home/os1/tempest/tempest/scenario/manager.py", line 211, in setUpClass
    username, tenant_name, password = cls.credentials()
  File "/home/os1/tempest/tempest/scenario/manager.py", line 226, in credentials
    return cls.isolated_creds.get_primary_creds()
  File "/home/os1/tempest/tempest/common/isolated_creds.py", line 333, in get_primary_creds
    self._get_tenant_id(tenant))
  File "/home/os1/tempest/tempest/common/isolated_creds.py", line 207, in _create_network_resources
    router = self._create_router(router_name, tenant_id)
  File "/home/os1/tempest/tempest/common/isolated_creds.py", line 265, in _create_router
    resp_body = self.network_admin_client.create_router(body)
  File "/usr/local/lib/python2.7/dist-packages/neutronclient/v2_0/client.py", line 108, in with_params
    ret = self.function(instance, *args, **kwargs)
  File "/usr/local/lib/python2.7/dist-packages/neutronclient/v2_0/client.py", line 388, in create_router
    return self.post(self.routers_path, body=body)
  File "/usr/local/lib/python2.7/dist-packages/neutronclient/v2_0/client.py", line 1188, in post
    headers=headers, params=params)
  File "/usr/local/lib/python2.7/dist-packages/neutronclient/v2_0/client.py", line 1111, in do_request
    self._handle_fault_response(status_code, replybody)
  File "/usr/local/lib/python2.7/dist-packages/neutronclient/v2_0/client.py", line 1081, in _handle_fault_response
    exception_handler_v20(status_code, des_error_body)
  File "/usr/local/lib/python2.7/dist-packages/neutronclient/v2_0/client.py", line 81, in exception_handler_v20
    message=error_dict)
NeutronClientException: Invalid input for external_gateway_info. Reason: '' is not a valid UUID.
0
]
tags: -worker-0
time: 2014-01-17 14:31:21.567567Z
tags: worker-0
test: process-returncode
time: 2014-01-17 14:31:21.567567Z
failure: process-returncode [ multipart
Content-Type: test/plain;charset=utf8
traceback
C
returncode 10
]
tags: -worker-0
