time: 2014-01-18 21:30:49.735215Z
tags: worker-0
test: tempest.scenario.test_minimum_basic.TestMinimumBasicScenario.test_minimum_basic_scenario[compute,image,network,volume]
time: 2014-01-18 21:39:11.630950Z
failure: tempest.scenario.test_minimum_basic.TestMinimumBasicScenario.test_minimum_basic_scenario[compute,image,network,volume] [ multipart
Content-Type: text/plain;charset="utf8"
pythonlogging:''
0
Content-Type: text/plain;charset="utf8"
stderr
0
Content-Type: text/plain;charset="utf8"
stdout
0
Content-Type: text/x-traceback;charset="utf8",language="python"
traceback
5FA
Traceback (most recent call last):
  File "/home/os1/tempest/tempest/scenario/test_minimum_basic.py", line 181, in test_minimum_basic_scenario
    self.ssh_to_server()
  File "/home/os1/tempest/tempest/scenario/test_minimum_basic.py", line 149, in ssh_to_server
    self.linux_client = self.get_remote_client(self.floating_ip.floating_ip_address)
  File "/home/os1/tempest/tempest/scenario/manager.py", line 475, in get_remote_client
    return RemoteClient(ip, username, pkey=private_key)
  File "/home/os1/tempest/tempest/common/utils/linux/remote_client.py", line 47, in __init__
    if not self.ssh_client.test_connection_auth():
  File "/home/os1/tempest/tempest/common/ssh.py", line 149, in test_connection_auth
    connection = self._get_ssh_connection()
  File "/home/os1/tempest/tempest/common/ssh.py", line 65, in _get_ssh_connection
    timeout=self.timeout, pkey=self.pkey)
  File "/usr/local/lib/python2.7/dist-packages/paramiko/client.py", line 305, in connect
    retry_on_signal(lambda: sock.connect(addr))
  File "/usr/local/lib/python2.7/dist-packages/paramiko/util.py", line 278, in retry_on_signal
    return function()
  File "/usr/local/lib/python2.7/dist-packages/paramiko/client.py", line 305, in <lambda>
    retry_on_signal(lambda: sock.connect(addr))
  File "/usr/lib/python2.7/socket.py", line 224, in meth
    return getattr(self._sock,name)(*args)
  File "/usr/local/lib/python2.7/dist-packages/fixtures/_fixtures/timeout.py", line 52, in signal_handler
    raise TimeoutException()
TimeoutException
0
]
tags: -worker-0
time: 2014-01-18 21:39:33.412367Z
tags: worker-0
test: tearDownClass (tempest.scenario.test_minimum_basic.TestMinimumBasicScenario)
time: 2014-01-18 21:39:33.412367Z
failure: tearDownClass (tempest.scenario.test_minimum_basic.TestMinimumBasicScenario) [ multipart
Content-Type: text/x-traceback;charset="utf8",language="python"
traceback
455
Traceback (most recent call last):
  File "/home/os1/tempest/tempest/scenario/manager.py", line 248, in tearDownClass
    thing.delete()
  File "/usr/local/lib/python2.7/dist-packages/cinderclient/v1/volumes.py", line 35, in delete
    self.manager.delete(self)
  File "/usr/local/lib/python2.7/dist-packages/cinderclient/v1/volumes.py", line 228, in delete
    self._delete("/volumes/%s" % base.getid(volume))
  File "/usr/local/lib/python2.7/dist-packages/cinderclient/base.py", line 162, in _delete
    resp, body = self.api.client.delete(url)
  File "/usr/local/lib/python2.7/dist-packages/cinderclient/client.py", line 216, in delete
    return self._cs_request(url, 'DELETE', **kwargs)
  File "/usr/local/lib/python2.7/dist-packages/cinderclient/client.py", line 174, in _cs_request
    **kwargs)
  File "/usr/local/lib/python2.7/dist-packages/cinderclient/client.py", line 157, in request
    raise exceptions.from_response(resp, body)
BadRequest: Invalid volume: Volume status must be available or error, but current status is: in-use (HTTP 400) (Request-ID: req-be831f71-4064-4e39-85a1-65bdadc54e15)
0
]
tags: -worker-0
time: 2014-01-18 21:39:33.468509Z
tags: worker-0
test: process-returncode
time: 2014-01-18 21:39:33.468509Z
failure: process-returncode [ multipart
Content-Type: test/plain;charset=utf8
traceback
C
returncode 10
]
tags: -worker-0
