time: 2014-01-20 13:22:36.660871Z
tags: worker-0
test: tempest.scenario.test_minimum_basic.TestMinimumBasicScenario.test_minimum_basic_scenario[compute,image,network,volume]
time: 2014-01-20 13:30:57.304470Z
failure: tempest.scenario.test_minimum_basic.TestMinimumBasicScenario.test_minimum_basic_scenario[compute,image,network,volume] [ multipart
Content-Type: text/plain;charset="utf8"
pythonlogging:''
0
Content-Type: text/plain;charset="utf8"
stderr
0
Content-Type: text/plain;charset="utf8"
stdout
0
Content-Type: text/x-traceback;charset="utf8",language="python"
traceback
488
Traceback (most recent call last):
  File "/home/os1/tempest/tempest/scenario/test_minimum_basic.py", line 183, in test_minimum_basic_scenario
    self.check_partitions()
  File "/home/os1/tempest/tempest/scenario/test_minimum_basic.py", line 153, in check_partitions
    partitions = self.linux_client.get_partitions()
  File "/home/os1/tempest/tempest/common/utils/linux/remote_client.py", line 77, in get_partitions
    output = self.ssh_client.exec_command(command)
  File "/home/os1/tempest/tempest/common/ssh.py", line 110, in exec_command
    channel = transport.open_session()
  File "/usr/local/lib/python2.7/dist-packages/paramiko/transport.py", line 662, in open_session
    return self.open_channel('session')
  File "/usr/local/lib/python2.7/dist-packages/paramiko/transport.py", line 759, in open_channel
    event.wait(0.1);
  File "/usr/lib/python2.7/threading.py", line 403, in wait
    self.__cond.wait(timeout)
  File "/usr/lib/python2.7/threading.py", line 262, in wait
    _sleep(delay)
  File "/usr/local/lib/python2.7/dist-packages/fixtures/_fixtures/timeout.py", line 52, in signal_handler
    raise TimeoutException()
TimeoutException
0
]
tags: -worker-0
time: 2014-01-20 13:31:17.828308Z
tags: worker-0
test: tearDownClass (tempest.scenario.test_minimum_basic.TestMinimumBasicScenario)
time: 2014-01-20 13:31:17.828308Z
failure: tearDownClass (tempest.scenario.test_minimum_basic.TestMinimumBasicScenario) [ multipart
Content-Type: text/x-traceback;charset="utf8",language="python"
traceback
455
Traceback (most recent call last):
  File "/home/os1/tempest/tempest/scenario/manager.py", line 248, in tearDownClass
    thing.delete()
  File "/usr/local/lib/python2.7/dist-packages/cinderclient/v1/volumes.py", line 35, in delete
    self.manager.delete(self)
  File "/usr/local/lib/python2.7/dist-packages/cinderclient/v1/volumes.py", line 228, in delete
    self._delete("/volumes/%s" % base.getid(volume))
  File "/usr/local/lib/python2.7/dist-packages/cinderclient/base.py", line 162, in _delete
    resp, body = self.api.client.delete(url)
  File "/usr/local/lib/python2.7/dist-packages/cinderclient/client.py", line 216, in delete
    return self._cs_request(url, 'DELETE', **kwargs)
  File "/usr/local/lib/python2.7/dist-packages/cinderclient/client.py", line 174, in _cs_request
    **kwargs)
  File "/usr/local/lib/python2.7/dist-packages/cinderclient/client.py", line 157, in request
    raise exceptions.from_response(resp, body)
BadRequest: Invalid volume: Volume status must be available or error, but current status is: in-use (HTTP 400) (Request-ID: req-8a49c3c8-a83d-4caa-a9eb-eebdeeb9018b)
0
]
tags: -worker-0
time: 2014-01-20 13:31:17.888161Z
tags: worker-0
test: process-returncode
time: 2014-01-20 13:31:17.888161Z
failure: process-returncode [ multipart
Content-Type: test/plain;charset=utf8
traceback
C
returncode 10
]
tags: -worker-0
