time: 2014-01-20 14:33:32.356370Z
tags: worker-0
test: tempest.scenario.test_minimum_basic.TestMinimumBasicScenario.test_minimum_basic_scenario[compute,image,network,volume]
time: 2014-01-20 14:34:50.685292Z
failure: tempest.scenario.test_minimum_basic.TestMinimumBasicScenario.test_minimum_basic_scenario[compute,image,network,volume] [ multipart
Content-Type: text/plain;charset="utf8"
pythonlogging:''
39
2014-01-20 15:34:50,683 Request returned failure status.
0
Content-Type: text/plain;charset="utf8"
stderr
0
Content-Type: text/plain;charset="utf8"
stdout
0
Content-Type: text/x-traceback;charset="utf8",language="python"
traceback
45E
Traceback (most recent call last):
  File "/home/os1/tempest/tempest/scenario/test_minimum_basic.py", line 169, in test_minimum_basic_scenario
    self.nova_boot()
  File "/home/os1/tempest/tempest/scenario/test_minimum_basic.py", line 102, in nova_boot
    create_kwargs=create_kwargs)
  File "/home/os1/tempest/tempest/scenario/manager.py", line 412, in create_server
    self.status_timeout(client.servers, server.id, 'ACTIVE')
  File "/home/os1/tempest/tempest/scenario/manager.py", line 304, in status_timeout
    not_found_exception=not_found_exception)
  File "/home/os1/tempest/tempest/scenario/manager.py", line 358, in _status_timeout
    self.config.compute.build_interval):
  File "/home/os1/tempest/tempest/test.py", line 290, in call_until_true
    if func():
  File "/home/os1/tempest/tempest/scenario/manager.py", line 349, in check_status
    raise exceptions.BuildErrorException(message)
BuildErrorException: Server %(server_id)s failed to build and is in ERROR status
Details: <Server: scenario-server--tempest-1274966508> failed to get to expected status.                           In ERROR state.
0
Content-Type: text/x-traceback;charset="utf8",language="python"
traceback-1
2AC
Traceback (most recent call last):
  File "/usr/local/lib/python2.7/dist-packages/glanceclient/v1/images.py", line 226, in delete
    self._delete("/v1/images/%s" % base.getid(image))
  File "/usr/local/lib/python2.7/dist-packages/glanceclient/common/base.py", line 62, in _delete
    self.api.raw_request('DELETE', url)
  File "/usr/local/lib/python2.7/dist-packages/glanceclient/common/http.py", line 289, in raw_request
    return self._http_request(url, method, **kwargs)
  File "/usr/local/lib/python2.7/dist-packages/glanceclient/common/http.py", line 249, in _http_request
    raise exc.from_response(resp, body_str)
HTTPInternalServerError: HTTPInternalServerError (HTTP 500)
0
]
tags: -worker-0
time: 2014-01-20 14:34:54.518711Z
tags: worker-0
test: process-returncode
time: 2014-01-20 14:34:54.518711Z
failure: process-returncode [ multipart
Content-Type: test/plain;charset=utf8
traceback
C
returncode 10
]
tags: -worker-0
