time: 2013-12-19 15:53:47.226408Z
tags: worker-0
test: tempest.scenario.test_volume_boot_pattern.TestVolumeBootPattern.test_volume_boot_pattern[compute,image,volume]
time: 2013-12-19 16:00:37.700332Z
failure: tempest.scenario.test_volume_boot_pattern.TestVolumeBootPattern.test_volume_boot_pattern[compute,image,volume] [ multipart
Content-Type: text/plain;charset="utf8"
pythonlogging:''
0
Content-Type: text/plain;charset="utf8"
stderr
0
Content-Type: text/plain;charset="utf8"
stdout
0
Content-Type: text/x-traceback;charset="utf8",language="python"
traceback
391
Traceback (most recent call last):
  File "/home/os1/tempest/tempest/scenario/test_volume_boot_pattern.py", line 161, in test_volume_boot_pattern
    keypair)
  File "/home/os1/tempest/tempest/scenario/test_volume_boot_pattern.py", line 129, in _ssh_to_server
    private_key=keypair.private_key)
  File "/home/os1/tempest/tempest/scenario/manager.py", line 475, in get_remote_client
    return RemoteClient(ip, username, pkey=private_key)
  File "/home/os1/tempest/tempest/common/utils/linux/remote_client.py", line 47, in __init__
    if not self.ssh_client.test_connection_auth():
  File "/home/os1/tempest/tempest/common/ssh.py", line 149, in test_connection_auth
    connection = self._get_ssh_connection()
  File "/home/os1/tempest/tempest/common/ssh.py", line 77, in _get_ssh_connection
    password=self.password)
SSHTimeout: Connection to the 10.10.13.202 via SSH timed out.
User: cirros, Password: None
0
]
tags: -worker-0
time: 2013-12-19 16:00:38.505462Z
tags: worker-0
test: tearDownClass (tempest.scenario.test_volume_boot_pattern.TestVolumeBootPattern)
time: 2013-12-19 16:00:38.505462Z
failure: tearDownClass (tempest.scenario.test_volume_boot_pattern.TestVolumeBootPattern) [ multipart
Content-Type: text/x-traceback;charset="utf8",language="python"
traceback
599
Traceback (most recent call last):
  File "/home/os1/tempest/tempest/scenario/manager.py", line 248, in tearDownClass
    thing.delete()
  File "/home/os1/tempest/tempest/api/network/common.py", line 90, in delete
    self.client.delete_floatingip(self.id)
  File "/usr/local/lib/python2.7/dist-packages/neutronclient/v2_0/client.py", line 108, in with_params
    ret = self.function(instance, *args, **kwargs)
  File "/usr/local/lib/python2.7/dist-packages/neutronclient/v2_0/client.py", line 449, in delete_floatingip
    return self.delete(self.floatingip_path % (floatingip))
  File "/usr/local/lib/python2.7/dist-packages/neutronclient/v2_0/client.py", line 1179, in delete
    headers=headers, params=params)
  File "/usr/local/lib/python2.7/dist-packages/neutronclient/v2_0/client.py", line 1168, in retry_request
    headers=headers, params=params)
  File "/usr/local/lib/python2.7/dist-packages/neutronclient/v2_0/client.py", line 1111, in do_request
    self._handle_fault_response(status_code, replybody)
  File "/usr/local/lib/python2.7/dist-packages/neutronclient/v2_0/client.py", line 1081, in _handle_fault_response
    exception_handler_v20(status_code, des_error_body)
  File "/usr/local/lib/python2.7/dist-packages/neutronclient/v2_0/client.py", line 93, in exception_handler_v20
    message=msg)
NeutronClientException: 404-{u'QuantumError': u'Floating IP a82b928a-fb0b-4e3d-bd74-031229019a5b could not be found'}
0
]
tags: -worker-0
time: 2013-12-19 16:00:38.559652Z
tags: worker-0
test: process-returncode
time: 2013-12-19 16:00:38.559652Z
failure: process-returncode [ multipart
Content-Type: test/plain;charset=utf8
traceback
C
returncode 10
]
tags: -worker-0
