time: 2013-12-26 21:28:21.111019Z
tags: worker-0
test: tempest.scenario.test_server_basic_ops.TestServerBasicOps.test_server_basicops[compute,network]
time: 2013-12-26 21:29:25.797966Z
failure: tempest.scenario.test_server_basic_ops.TestServerBasicOps.test_server_basicops[compute,network] [ multipart
Content-Type: text/plain;charset="utf8"
pythonlogging:''
0
Content-Type: text/plain;charset="utf8"
stderr
0
Content-Type: text/plain;charset="utf8"
stdout
0
Content-Type: text/x-traceback;charset="utf8",language="python"
traceback
463
Traceback (most recent call last):
  File "/home/os1/tempest/tempest/scenario/test_server_basic_ops.py", line 135, in test_server_basicops
    self.boot_instance()
  File "/home/os1/tempest/tempest/scenario/test_server_basic_ops.py", line 86, in boot_instance
    create_kwargs=create_kwargs)
  File "/home/os1/tempest/tempest/scenario/manager.py", line 412, in create_server
    self.status_timeout(client.servers, server.id, 'ACTIVE')
  File "/home/os1/tempest/tempest/scenario/manager.py", line 304, in status_timeout
    not_found_exception=not_found_exception)
  File "/home/os1/tempest/tempest/scenario/manager.py", line 358, in _status_timeout
    self.config.compute.build_interval):
  File "/home/os1/tempest/tempest/test.py", line 290, in call_until_true
    if func():
  File "/home/os1/tempest/tempest/scenario/manager.py", line 349, in check_status
    raise exceptions.BuildErrorException(message)
BuildErrorException: Server %(server_id)s failed to build and is in ERROR status
Details: <Server: scenario-server--tempest-875191795> failed to get to expected status.                           In ERROR state.
0
]
tags: -worker-0
time: 2013-12-26 21:29:50.627062Z
tags: worker-0
test: process-returncode
time: 2013-12-26 21:29:50.627062Z
failure: process-returncode [ multipart
Content-Type: test/plain;charset=utf8
traceback
C
returncode 10
]
tags: -worker-0
